Workbook

Sheet PDF Use Case Analysis Translati
A1: POLE | B1: Entity | C1: Use Case Name | D1: Intent (User Story) | E1: Target Workshop (Squad) | F1: Reasoning (Workshop) | G1: Agent Archetype | H1: Reasoning (Archetype) | I1: Target Maturity | J1: Data Sources & Tools | K1: Value/ROI
A2: CPBS | B2: CPBS | C2: Incident Diagnosis & MTTR | D2: I want to reduce MTTR by automating the correlation and diagnosis of production incidents. | E2: Real Time Madrid | F2: Crisis management and real-time incidents. | G2: Investigator | H2: Analyzes symptoms to find the root cause (RCA). | I2: Lvl 4 | J2: ServiceNow, Dynatrace, Golden Events. | K2: -30% MTTR, reduced on-call fatigue. | L2: =VLOOKUP(C2,Feuil1!A:C,2,FALSE) -> 3 | M2: =VLOOKUP(C2,Feuil1!A:C,3,FALSE) -> Premature. RCA requires perfect correlation between Topology and Golden Events. Risk of hallucination is high without synthesized logs.
A3: CPBS | B3: CPBS | C3: Vuln & Threat Prioritization | D3: I want to prioritize vulnerabilities by correlating them with critical assets and business context. | E3: Integrity Milan | F3: Vulnerability management and security compliance. | G3: Guardian | H3: Validates compliance and assesses security risk. | I3: Lvl 3 | J3: Tanium, CMDB, SIEM, Baselines. | K3: Reduced exposure window, focus on real risks. | L3: =VLOOKUP(C3,Feuil1!A:C,2,FALSE) -> 4 | M3: =VLOOKUP(C3,Feuil1!A:C,3,FALSE) -> High Potential. Simple graph traversal linking Assets to CVEs. High security value and technically feasible with current Graflo ingestion.
A4: CPBS | B4: CPBS | C4: FinOps Agent | D4: I want to optimize Cloud/Infra costs by correlating billing and actual usage. | E4: Benfiscal Lisboa | F4: Cost optimization and financial capacity management. | G4: Reporter | H4: Analyzes and reports savings opportunities. | I4: Lvl 3 | J4: CMDB, Billing API, Usage Metrics. | K4: Direct gains (€), reduced waste. | L4: =VLOOKUP(C4,Feuil1!A:C,2,FALSE) -> 2 | M4: =VLOOKUP(C4,Feuil1!A:C,3,FALSE) -> Complex. Billing data is often aggregated and poorly mapped to technical CIs. High risk of 'Garbage In
A5: CPBS | B5: CPBS | C5: Change Impact & CAB | D5: I want to assess the impact (blast radius) of a change before the CAB. | E5: Pilotage St-Germain | F5: Change governance and risk validation. | G5: Guardian | H5: "Is it authorized/risky?" Preventive validation. | I5: Lvl 3 | J5: ServiceNow Change, CMDB Topology. | K5: Faster CAB, fewer change-related incidents. | L5: =VLOOKUP(C5,Feuil1!A:C,2,FALSE) -> 5 | M5: =VLOOKUP(C5,Feuil1!A:C,3,FALSE) -> Flagship. The 'Killer Use Case' for Graph. Native calculation of Blast Radius (recursive dependency check). Critical for stability.
A6: CPBS | B6: CPBS | C6: Prediction & Proactive Stability | D6: I want to detect weak signals and predict incidents before impact. | E6: Observability Marseille | F6: Predictive analysis on metrics and events. | G6: Investigator | H6: Investigates abnormal patterns (proactive). | I6: Lvl 4 | J6: Dynatrace, Golden Signals, Incident History. | K6: Prevention of major outages, increased stability. | L6: =VLOOKUP(C6,Feuil1!A:C,2,FALSE) -> 1 | M6: =VLOOKUP(C6,Feuil1!A:C,3,FALSE) -> Out of Scope. Relies on predictive Machine Learning (time series analysis) on metrics
A7: CPBS | B7: CPBS | C7: Governance & Doc Agent | D7: I want to automatically generate CTO reports and keep documentation up to date. | E7: Pilotage St-Germain | F7: Managerial reporting and documentary compliance. | G7: Reporter | H7: Synthesizes information for humans. | I7: Lvl 2 | J7: Project KPIs, Confluence, Audit logs. | K7: Time saved on admin tasks. | L7: =VLOOKUP(C7,Feuil1!A:C,2,FALSE) -> 3 | M7: =VLOOKUP(C7,Feuil1!A:C,3,FALSE) -> Dependency. Agent is mute until the Knowledge Base (GraphRAG) is populated with valid
A8: CPBS | B8: CPBS | C8: Data Integration & Quality | D8: I want to reconcile repositories and clean the CMDB automatically. | E8: Observability Marseille | F8: Data quality is the foundation of observability. | G8: Mapper | H8: Maps and cleans the ground truth. | I8: Lvl 3 | J8: CMDB, Discovery, Golden Sources. | K8: Trust in Twin data. | L8: =VLOOKUP(C8,Feuil1!A:C,2,FALSE) -> 5 | M8: =VLOOKUP(C8,Feuil1!A:C,3,FALSE) -> Build Enabler. Critical agent to detect orphan nodes and gaps in the Graph. Essential to validate Graflo ingestion pipelines.
A9: CPBS | B9: CPBS | C9: Config Compliance | D9: I want to detect configuration drifts compared to the standard. | E9: Integrity Milan | F9: Technical compliance and security (Hardening). | G9: Guardian | H9: Verifies alignment with the Golden Copy. | I9: Lvl 3 | J9: CMDB, Tanium, SATS Baselines. | K9: Reduced attack surface, facilitated audit. | L9: =VLOOKUP(C9,Feuil1!A:C,2,FALSE) -> 4 | M9: =VLOOKUP(C9,Feuil1!A:C,3,FALSE) -> Robust. Structured comparison (Config File vs Golden Rule). Low risk and high value for maintaining security baselines.
A10: CPBS | B10: CPBS | C10: Flow Validation & Monitoring | D10: I want to validate flow opening requests against the validated architecture. | E10: Integrity Milan | F10: Network security, flow validation. | G10: Guardian | H10: Validates the legitimacy of a flow. | I10: Lvl 2 | J10: Flow matrices, CMDB, Firewall Rules. | K10: Network security, time saved on validation. | L10: =VLOOKUP(C10,Feuil1!A:C,2,FALSE) -> 2 | M10: =VLOOKUP(C10,Feuil1!A:C,3,FALSE) -> Difficult. Mapping dynamic network flows requires real-time observability. Hard to capture in a static graph model.
A11: CPBS | B11: CPBS | C11: App Evolution Readiness | D11: I want to assess the impact of a version upgrade or migration on an app. | E11: Cloud Platform Barcelona | F11: Infra lifecycle management and modernization. | G11: Investigator | H11: Analyzes dependencies and compatibility risks. | I11: Lvl 3 | J11: CMDB, Architecture Doc, Compatibility Matrix. | K11: Secure migrations, less technical debt. | L11: =VLOOKUP(C11,Feuil1!A:C,2,FALSE) -> 4 | M11: =VLOOKUP(C11,Feuil1!A:C,3,FALSE) -> Useful. Pure impact analysis (e.g. Java 8 to 17 upgrade). Leverages topology to list obsolescence risks across the estate.
A12: CPBS | B12: CPBS | C12: Obsolescence & Lifecycle | D12: I want to orchestrate the lifecycle of assets (EOL/EOS) and certificates. | E12: Cloud Platform Barcelona | F12: MCO and LifeCycle Management. | G12: Runner | H12: Plans and prepares update actions. | I12: Lvl 3 | J12: CMDB, EOL Vendor Data, Certificates. | K12: Reduced obsolescence risk. | L12: =VLOOKUP(C12,Feuil1!A:C,2,FALSE) -> 5 | M12: =VLOOKUP(C12,Feuil1!A:C,3,FALSE) -> Quick Win. Simple query on attributes (EOL Date). Immediate visual ROI for management to identify technical debt.
A13: CPBS | B13: CPBS | C13: DevOps & Assisted Coding | D13: I want to optimize CI/CD pipelines and secure infra code. | E13: Cloud Platform Barcelona | F13: Platform Engineering and CI/CD chain. | G13: Runner | H13: Accelerates delivery and validates code (IaC). | I13: Lvl 3 | J13: Gitlab CI, SonarQube, Pipeline Logs. | K13: Deployment reliability, increased velocity. | L13: =VLOOKUP(C13,Feuil1!A:C,2,FALSE) -> 1 | M13: =VLOOKUP(C13,Feuil1!A:C,3,FALSE) -> Commodity. GitHub Copilot or similar tools do this better. No specific Digital Twin value added to the architecture.
... A65: TW | B65: Network | C65: Traffic Patterns + Chaos | D65: I want to simulate link failures and see the impact on traffic. | E65: Integrity Milan | F65: Network Resilience. | G65: Investigator | H65: Simulates traffic chaos. | I65: Lvl 3 | J65: Topology, Flows. | K65: Proven resilience. | L65: =VLOOKUP(C65,Feuil1!A:C,2,FALSE) -> 2 | M65: =VLOOKUP(C65,Feuil1!A:C,3,FALSE) -> Simulation. Simulating traffic loads requires heavy computation and advanced "What-If" capabilities.
B66: Validate major IT change (Backbone) | C66: I want to simulate a major migration (e.g., LDP to SR) on a twin. | D66: Pilotage St-Germain | E66: Architecture Validation. | F66: Investigator | G66: Complex migration simulation. | H66: Lvl 4 | I66: Network Digital Twin. | J66: Risk-free migration. | L66: =VLOOKUP(C66,Feuil1!A:C,2,FALSE) -> 5 | M66: =VLOOKUP(C66,Feuil1!A:C,3,FALSE) -> Flagship. Simulation on Graph is the ultimate goal. High value for planning major architecture shifts.
B67: Root Cause Analysis (RCA) | C67: I want to identify the root cause of complex degradation (Flapping). | D67: Real Time Madrid | E67: Network RCA. | F67: Investigator | G67: Deep causal analysis. | H67: Lvl 4 | I67: Syslogs, Twin. | J67: Auto expert diagnostic. | L67: =VLOOKUP(C67,Feuil1!A:C,2,FALSE) -> 3 | M67: =VLOOKUP(C67,Feuil1!A:C,3,FALSE) -> Investigator. Hard without Golden Events synthesis. Flapping is a temporal pattern hard to catch in a snapshot.
B68: Continous Resilliency Testing | C68: I want to test resilience via simulated outages at scale. | D68: Integrity Milan | E68: Network Chaos Engineering. | F68: Guardian | G68: Continuous resilience testing. | H68: Lvl 3 | I68: Batfish, Topology. | J68: Robust network. | L68: =VLOOKUP(C68,Feuil1!A:C,2,FALSE) -> 2 | M68: =VLOOKUP(C68,Feuil1!A:C,3,FALSE) -> Simulation. Requires advanced "What-If" scenario modeling which is complex to build initially.
A69: ITG | B69: ITG | C69: Assets Finder | D69: I want to find lost/missing assets and their history. | E69: Benfiscal Lisboa | F69: Asset Mgmt. | G69: Investigator | H69: Investigates lost asset. | I69: Lvl 2 | J69: ServiceNow HAM, Logs. | K69: Reliable inventory. | L69: =VLOOKUP(C69,Feuil1!A:C,2,FALSE) -> 4 | M69: =VLOOKUP(C69,Feuil1!A:C,3,FALSE) -> Mapper. Helps locate "Ghost Assets" that are active but missing from the CMDB. Good for graph building.
A70: ITG | B70: ITG | C70: Incident & Requests Analysis | D70: I want to analyze incident/request volumes and trends. | E70: Pilotage St-Germain | F70: ITIL Process Analysis. | G70: Reporter | H70: Macro trend analysis. | I70: Lvl 2 | J70: ServiceNow Reporting. | K70: Support steering. | L70: =VLOOKUP(C70,Feuil1!A:C,2,FALSE) -> 3 | M70: =VLOOKUP(C70,Feuil1!A:C,3,FALSE) -> Investigator. Standard analysis of ticket trends. Needs clean historical data to be effective.
A71: ITG | B71: ITG | C71: Knowledge Mgmt Analysis | D71: I want to analyze knowledge base usage to improve it. | E71: Main Elasticity | F71: Knowledge Management. | G71: Librarian | H71: Analyzes KB relevance. | I71: Lvl 2 | J71: KB usage stats. | K71: Useful and used KB. | L71: =VLOOKUP(C71,Feuil1!A:C,2,FALSE) -> 3 | M71: =VLOOKUP(C71,Feuil1!A:C,3,FALSE) -> Librarian. Gap analysis of the Knowledge Base. Identifying what documentation is missing is a good meta-use case.
A72: ITG | B72: ITG | C72: Quality survey Verbatims | D72: I want to analyze user verbatims to derive actions. | E72: Pilotage St-Germain | F72: User Experience. | G72: Reporter | H72: Sentiment/verbatim analysis. | I72: Lvl 2 | J72: Satisfaction surveys. | K72: UX Improvement. | L72: =VLOOKUP(C72,Feuil1!A:C,2,FALSE) -> 2 | M72: =VLOOKUP(C72,Feuil1!A:C,3,FALSE) -> Sentiment Analysis. Analyzing user feedback is useful but not a core IT Operations function.
A73: ITG | B73: ITG | C73: BoardBrief "Executive insights" | D73: I want concise executive summaries on health and risks. | E73: Pilotage St-Germain | F73: Management Reporting. | G73: Reporter | H73: Synthesis for decision makers. | I73: Lvl 3 | J73: Global KPIs. | K73: Rapid decision. | L73: =VLOOKUP(C73,Feuil1!A:C,2,FALSE) -> 2 | M73: =VLOOKUP(C73,Feuil1!A:C,3,FALSE) -> Reporter. High-level summary for execs. High admin value
A74: ITG | B74: ITG | C74: PagePilot (Translation) | D74: I want to translate and maintain multilingual content (SharePoint/SAM). | E74: Main Elasticity | F74: Communication/KM. | G74: Librarian | H74: Translation and content maintenance. | I74: Lvl 2 | J74: SharePoint Content. | K74: Global info accessibility. | L74: =VLOOKUP(C74,Feuil1!A:C,2,FALSE) -> 1 | M74: =VLOOKUP(C74,Feuil1!A:C,3,FALSE) -> Commodity. Translation and summarization are standard LLM features. Low structural value for the Twin.
A75: ITG | B75: ITG | C75: LiveFAQ.AAI | D75: I want to generate a dynamic FAQ from recurring tickets. | E75: Main Elasticity | F75: Self-Service / KM. | G75: Librarian | H75: Creates knowledge from incidents. | I75: Lvl 3 | J75: Tickets, Frequent Questions. | K75: Ticket deflection. | L75: =VLOOKUP(C75,Feuil1!A:C,2,FALSE) -> 3 | M75: =VLOOKUP(C75,Feuil1!A:C,3,FALSE) -> Librarian. Retrieval Augmented Generation (RAG) on documentation. Success depends 100% on the quality of the source KB.
A76: ITG | B76: ITG | C76: Proactive incident management | D76: I want to detect and resolve workstation incidents proactively. | E76: Real Time Madrid | F76: Proactive User Support. | G76: Runner | H76: Workstation remediation. | I76: Lvl 4 | J76: Workstation Logs (Systrack). | K76: Fewer support calls. | L76: =VLOOKUP(C76,Feuil1!A:C,2,FALSE) -> 3 | M76: =VLOOKUP(C76,Feuil1!A:C,3,FALSE) -> Investigator. Needs pattern recognition to detect "weak signals" before they become incidents.
A77: ITG | B77: ITG | C77: Proactive maintenance & lifeCycle | D77: I want to optimize hardware renewal (Maintenance cost vs new). | E77: Benfiscal Lisboa | F77: Hardware lifecycle management. | G77: Reporter | H77: Renewal decision aid. | I77: Lvl 3 | J77: Costs, Failures. | K77: Hardware ROI. | L77: =VLOOKUP(C77,Feuil1!A:C,2,FALSE) -> 5 | M77: =VLOOKUP(C77,Feuil1!A:C,3,FALSE) -> Mapper. Lifecycle management is Graph-native. Proactively flagging EOL assets is a Quick Win.
A78: ITG | B78: ITG | C78: Natural language IVR | D78: I want to route support calls via natural language. | E78: Real Time Madrid | F78: Telephony Front. | G78: Runner | H78: Routes the call. | I78: Lvl 3 | J78: Voice, Intents. | K78: Better user welcome. | L78: =VLOOKUP(C78,Feuil1!A:C,2,FALSE) -> 2 | M78: =VLOOKUP(C78,Feuil1!A:C,3,FALSE) -> Voice. Integrating with telephony systems is complex and distinct from the core Digital Twin scope.
A79: ITG | B79: ITG | C79: Standard incident resolution | D79: I want to automatically resolve simple incidents. | E79: Real Time Madrid | F79: Self-Healing. | G79: Runner | H79: Executes standard resolution. | I79: Lvl 4 | J79: Scripts, Tickets. | K79: Support efficiency. | L79: =VLOOKUP(C79,Feuil1!A:C,2,FALSE) -> 3 | M79: =VLOOKUP(C79,Feuil1!A:C,3,FALSE) -> Investigator. Retrieving standard procedures (SOPs) for known incidents. Good Librarian use case.
A80: ITG | B80: ITG | C80: Automatic Ticket fulfillment | D80: I want to automatically fill tickets during user exchange. | E80: Real Time Madrid | F80: Ticket Qualification. | G80: Runner | H80: Fills ticket fields. | I80: Lvl 2 | J80: Chat/Voice. | K80: Ticket data quality. | L80: =VLOOKUP(C80,Feuil1!A:C,2,FALSE) -> 1 | M80: =VLOOKUP(C80,Feuil1!A:C,3,FALSE) -> Runner. End-to-end automation of requests. Risky without a "Human in the Loop" for validation.
... A93: TW24 | B93: TW24 | C93: Proactive Update Notification | D93: I want to alert app owners of new vendor versions. | E93: Cloud Platform Barcelona | F93: Application MCO. | G93: Reporter | H93: Software version monitoring. | I93: Lvl 2 | J93: Vendor sources. | K93: Up-to-date fleet. | L93: =VLOOKUP(C93,Feuil1!A:C,2,FALSE) -> 4 | M93: =VLOOKUP(C93,Feuil1!A:C,3,FALSE) -> Mapper. Notify application owners based on Topology when a dependency is updated. Excellent Graph usage.
C94: Incident Report Extraction | D94: I want to automate the extraction and standardization of incident reports. | E94: Pilotage St-Germain | F94: Operational Reporting. | G94: Reporter | H94: Prepares reporting data. | I94: Lvl 2 | J94: ServiceNow, Excel. | K94: Reporting time saved. | L94: =VLOOKUP(C94,Feuil1!A:C,2,FALSE) -> 2 | M94: =VLOOKUP(C94,Feuil1!A:C,3,FALSE) -> Reporter. Standard reporting. Extracting key facts from messy ticket notes is a good NLP task.
C95: Carrier Change Conflict | D95: I want to check for change conflicts on backup links (Telco). | E95: Pilotage St-Germain | F95: Network Change Management. | G95: Guardian | H95: Detects schedule conflict. | I95: Lvl 2 | J95: Change Planning. | K95: Network availability. | L95: =VLOOKUP(C95,Feuil1!A:C,2,FALSE) -> 5 | M95: =VLOOKUP(C95,Feuil1!A:C,3,FALSE) -> Guardian. Detects collision in network changes using graph topology. High value for preventing outages.
C96: ADVA Device Backup | D96: I want to automate the monthly backup of ADVA devices. | E96: Cloud Platform Barcelona | F96: Infra Backup. | G96: Runner | H96: Executes backup. | I96: Lvl 3 | J96: Network Equipment. | K96: Config data security. | L96: =VLOOKUP(C96,Feuil1!A:C,2,FALSE) -> 4 | M96: =VLOOKUP(C96,Feuil1!A:C,3,FALSE) -> Guardian. Verifies backup compliance for network devices. Structured task suitable for automation.
A97: TW23 | B97: TW23 | C97: Verbo (Voice Channel) | D97: I want to replace the IVR with a conversational voice AI. | E97: Real Time Madrid | F97: Telephony Front. | G97: Runner | H97: Voice interface. | I97: Lvl 3 | J97: Voice. | K97: Customer experience. | L97: =VLOOKUP(C97,Feuil1!A:C,2,FALSE) -> 2 | M97: =VLOOKUP(C97,Feuil1!A:C,3,FALSE) -> Voice. Voice interface layer. Valid channel
A98: TW23 | B98: TW23 | C98: SmartRemedy | D98: I want to automatically resolve standard cases (VPN, Service). | E98: Real Time Madrid | F98: Self-Healing. | G98: Runner | H98: Executes remediation. | I98: Lvl 4 | J98: Auto scripts. | K98: Support offload. | L98: =VLOOKUP(C98,Feuil1!A:C,2,FALSE) -> 3 | M98: =VLOOKUP(C98,Feuil1!A:C,3,FALSE) -> Investigator. BMC Remedy specific helper. Contextual search within the Remedy ticket history.
A99: TW23 | B99: TW23 | C99: SmartKnowledge | D99: I want precise semantic search in the knowledge base. | E99: Main Elasticity | F99: Knowledge Management. | G99: Librarian | H99: Intelligent search engine. | I99: Lvl 2 | J99: Knowledge Base. | K99: Rapid answer. | L99: =VLOOKUP(C99,Feuil1!A:C,2,FALSE) -> 3 | M99: =VLOOKUP(C99,Feuil1!A:C,3,FALSE) -> Librarian. Knowledge Base interface. Success is purely dependent on the ingestion quality of the docs.
A100: PRODSEC | B100: PRODSEC | C100: Vulnerabilities Triage and Analysis | D100: I want to assess vulnerability exploitability in the BNPP context and identify false positives. | E100: Integrity Milan | F100: Vulnerability Management. | G100: Investigator | H100: Analyzes context to assess risk (Triage). | I100: Lvl 3 | J100: Tanium, Sysdig, Qualys, CTI, CMDB. | K100: High value, impacts all asset owners. | L100: =VLOOKUP(C100,Feuil1!A:C,2,FALSE) -> 4 | M100: =VLOOKUP(C100,Feuil1!A:C,3,FALSE) -> Guardian. Prioritization based on Asset criticality (Business Value) from the Graph.
A101: PRODSEC | B101: PRODSEC | C101: Vulnerabilities remediation support | D101: I want step-by-step guidance for patching and to rationalize remediation actions. | E101: Integrity Milan | F101: Remediation/Patching. | G101: Runner | H101: Orchestrates and guides remediation. | I101: Assisted | J101: ServiceNow Change, Procedures, Asset Card. | K101: High value, rationalizes planning. | L101: =VLOOKUP(C101,Feuil1!A:C,2,FALSE) -> 2 | M101: =VLOOKUP(C101,Feuil1!A:C,3,FALSE) -> Runner. Remediation guidance (Suggesting the patch) is safer than auto-fix. Good step forward.
A102: PRODSEC | B102: PRODSEC | C102: Cyber SOC Threat Hunting | D102: I want chatbot assistance to construct threat hypotheses and collect evidence. | E102: Integrity Milan | F102: SOC / Threat Intelligence. | G102: Investigator | H102: Investigates threats and collects evidence. | I102: Assisted | J102: CTI, Open source reports, EDR (Elastic). | K102: Better Threat Hunting level. | L102: =VLOOKUP(C102,Feuil1!A:C,2,FALSE) -> 3 | M102: =VLOOKUP(C102,Feuil1!A:C,3,FALSE) -> Investigator. Complex. Requires deep integration with SIEM and Threat Intel feeds.
A103: PRODSEC | B103: PRODSEC | C103: Cyber SOC Alert Contextualization | D103: I want to contextualize and prioritize SOC alerts with user/entity summaries. | E103: Integrity Milan | F103: SOC / Incident Response. | G103: Investigator | H103: Enriches and scores alerts. | I103: Assisted | J103: SOC Alerts, CTI, Cyber Incidents. | K103: Better prioritization and response time. | L103: =VLOOKUP(C103,Feuil1!A:C,2,FALSE) -> 5 | M103: =VLOOKUP(C103,Feuil1!A:C,3,FALSE) -> Investigator. Enriches raw alerts with Graph context (Owner
...

Sheet Feuil1
A1: Use Case Name | B1: DTES (1-5) | C1: Commentaire & Justification (Why?)
A2: Incident Diagnosis & MTTR | B2: 3 | C2: Premature. RCA requires perfect correlation between Topology and Golden Events. Risk of hallucination is high without synthesized logs.
A3: Vuln & Threat Prioritization | B3: 4 | C3: High Potential. Simple graph traversal linking Assets to CVEs. High security value and technically feasible with current Graflo ingestion.
A4: FinOps Agent | B4: 2 | C4: Complex. Billing data is often aggregated and poorly mapped to technical CIs. High risk of 'Garbage In | D4: Garbage Out' without strict tagging.
A5: Change Impact & CAB | B5: 5 | C5: Flagship. The 'Killer Use Case' for Graph. Native calculation of Blast Radius (recursive dependency check). Critical for stability.
A6: Prediction & Proactive Stability | B6: 1 | C6: Out of Scope. Relies on predictive Machine Learning (time series analysis) on metrics | D6: not on Graph/LLM reasoning logic.
A7: Governance & Doc Agent | B7: 3 | C7: Dependency. Agent is mute until the Knowledge Base (GraphRAG) is populated with valid | D7: vectorized documentation.
A8: Data Integration & Quality | B8: 5 | C8: Build Enabler. Critical agent to detect orphan nodes and gaps in the Graph. Essential to validate Graflo ingestion pipelines.
A9: Config Compliance | B9: 4 | C9: Robust. Structured comparison (Config File vs Golden Rule). Low risk and high value for maintaining security baselines.
A10: Flow Validation & Monitoring | B10: 2 | C10: Difficult. Mapping dynamic network flows requires real-time observability. Hard to capture in a static graph model.
A11: App Evolution Readiness | B11: 4 | C11: Useful. Pure impact analysis (e.g. Java 8 to 17 upgrade). Leverages topology to list obsolescence risks across the estate.
A12: Obsolescence & Lifecycle | B12: 5 | C12: Quick Win. Simple query on attributes (EOL Date). Immediate visual ROI for management to identify technical debt.
A13: DevOps & Assisted Coding | B13: 1 | C13: Commodity. GitHub Copilot or similar tools do this better. No specific Digital Twin value added to the architecture.
A14: Ubiquitous (Support Assistant) | B14: 2 | C14: Vague. 'I want to know everything' leads to deception. Requires a massive | D14: curated Knowledge Base to be effective.
A15: GSS Interact | B15: 5 | C15: Must Have. 'Who owns this App?'. Immediate value for L1 Support via simple Graph attribute lookup (Owner/Steward).
A16: CFT File Locator | B16: 3 | C16: Specific. Requires ingestion of complex application logs (CFT). Defer until Log Synthesis layer is mature.
A17: MyIAM+ Chatbot | B17: 2 | C17: Sensitive. Modifying access (IAM) requires RBAC maturity that the Twin does not yet have. High security risk.
A18: PerfDB (DB Performance) | B18: 3 | C18: Monitoring. The Twin must explain *why* it is slow (Context) | D18: not just alert *that* it is slow. Needs metric integration.
A19: NAC Logs Analyst | B19: 2 | C19: Forbidden. Golden Rule violation: No Raw Logs in the Twin. Must build the Event Synthesizer first.
A20: Voice-to-Ticket Assistant | B20: 1 | C20: Gadget. Speech-to-text is a commodity. Does not help build the fundamental structure or intelligence of the Twin.
A21: Ticket Quality & Compliance | B21: 4 | C21: Data Quality. LLM cleans the source (ServiceNow) by enforcing correct field population and categorization. High hygiene value.
A22: Ticket Pattern Mining | B22: 3 | C22: Historical. Requires ingesting years of tickets. Semantic search on tickets is powerful but heavy for 'Day 1' implementation.
A23: Infra Capacity Management | B23: 2 | C23: Forecast. Relies on statistical capacity planning and linear regression | D23: not Generative AI reasoning.
A24: Invoice & Supplier Inventory | B24: 2 | C24: Admin. Low operational value for pure IT Ops. Mostly administrative data mapping.
A25: Automated Incident Routing | B25: 5 | C25: Efficiency. Uses topology to find the technical owner and route tickets directly. Drastically reduces 'Ping-Pong'.
A26: Automated CAB | B26: 4 | C26: Extension. Automates validation for low-risk changes detected by the Graph (e.g. standard changes with 0 impact).
A27: Canary Solution | B27: 1 | C27: Expert. Progressive deployment strategies (Canary/Blue-Green). Too risky to automate via Twin without extreme maturity.
A28: Real Time Impact Analysis | B28: 5 | C28: Core Value. The promise of the Twin: visualizing the cascade of incidents in real-time on the topology.
A29: Reg IT Controls | B29: 3 | C29: Audit. Feasible but often dry. Involves fetching evidence for regulatory checklists (GDPR | D29: etc.).
A30: Enhanced Sanity Check | B30: 4 | C30: Reassurance. Running 'Read-only' tests in the morning to verify service health. Low risk | D30: high trust builder for Ops.
A31: Command Center Automation | B31: 1 | C31: Danger. Critical manual actions in the Command Center. Do not automate now due to safety risks.
A32: Expert CTLM Agent | B32: 3 | C32: Niche. Useful only if Control-M technical documentation and job definitions are ingested into the KB.
A33: Intelligent Incident & On-Call | B33: 4 | C33: Support. Provides context (who to call | D33: impact | E33: recent changes) to on-call staff at 3 AM. Very useful.
A34: Dynatrace Config Guardian | B34: 5 | C34: Consistency. Verifies consistency between Inventory (CMDB/Graph) and Monitoring (Dynatrace). Vital hygiene check.
A35: DB Insight Agent | B35: 3 | C35: Silo. Too focused on DB internals. We need transverse agents first | D35: not deep-dive database experts.
A36: SmartPrep Change | B36: 3 | C36: Assistant. Pre-fills change requests using historical patterns to reduce admin burden on technical teams.
A37: CH CMDB Data Quality | B37: 5 | C37: Data Quality. Vital for the Swiss subsidiary. Cleans data at the source in a continuous loop.
A38: Shared Drive Access Provisionning | B38: 1 | C38: Commodity. Basic administrative task with low intellectual value added for a Cognitive Agent.
A39: User VDI Provisioning | B39: 1 | C39: Commodity. Standard provisioning task better handled by existing ITSM workflows than an AI Agent.
A40: Prodsec network security Validator | B40: 4 | C40: Validation. Verifies simple flow rules (Firewall matrix) before implementation. Secure and structured.
...
